<?xml version="1.0" ?>
<!-- =================================================================================== -->
<!-- |    This document was autogenerated by xacro from robot_arm_urdf.urdf            | -->
<!-- |    EDITING THIS FILE BY HAND IS NOT RECOMMENDED                                 | -->
<!-- =================================================================================== -->
<!-- 4 DoF Robot Arm with Soft Gripper created by Berk GULER (bilgisim@gmail.com) -->
<!-- This URDF was automatically created by SolidWorks to URDF Exporter! Originally created by Stephen Brawner (brawner@gmail.com) 
     Commit Version: 1.5.1-0-g916b5db  Build Version: 1.5.7152.31018
     For more information, please see http://wiki.ros.org/sw_urdf_exporter -->

<robot xmlns:xacro="http://www.ros.org/wiki/xacro" name="robot_arm_urdf">

<xacro:macro name = "transmission_block" params="joint_name">
<transmission name="tran1">
	<type>transmission_interface/SimpleTransmission</type>
	<joint name="${joint_name}">
	<hardwareInterface>hardware_interface/EffortJointInterface</hardwareInterface>
	</joint>
	<actuator name="motor1">
	<hardwareInterface>hardware_interface/EffortJointInterface</hardwareInterface>
	 <mechanicalReduction>1</mechanicalReduction>
	</actuator>
</transmission>
</xacro:macro>

<gazebo reference="robot_base">
    <mu1>0.2</mu1>
    <mu2>0.2</mu2>
    <selfCollide>true</selfCollide>
    <material>Gazebo/DarkGrey</material>
  </gazebo>

<gazebo reference="robot_base_link">
    <mu1>0.2</mu1>
    <mu2>0.2</mu2>
    <selfCollide>true</selfCollide>
    <material>Gazebo/Orange</material>
  </gazebo>

<gazebo reference="shoulder_link">
    <mu1>0.2</mu1>
    <mu2>0.2</mu2>
    <selfCollide>true</selfCollide>
    <material>Gazebo/Black</material>
  </gazebo>

<gazebo reference="elbow_link">
    <mu1>0.2</mu1>
    <mu2>0.2</mu2>
    <selfCollide>true</selfCollide>
    <material>Gazebo/Orange</material>
  </gazebo>

<gazebo reference="wrist_link">
    <mu1>0.2</mu1>
    <mu2>0.2</mu2>
    <selfCollide>true</selfCollide>
    <material>Gazebo/Orange</material>
  </gazebo>

<gazebo reference="gripper_link">
    <mu1>0.2</mu1>
    <mu2>0.2</mu2>
    <selfCollide>true</selfCollide>
    <material>Gazebo/DarkMagentaTransparent</material>
  </gazebo>

<gazebo reference="camera_link">
    <mu1>0.2</mu1>
    <mu2>0.2</mu2>
    <selfCollide>true</selfCollide>
    <material>Gazebo/GreenGlow</material>
  </gazebo>

<gazebo reference="lidar_link">
    <mu1>0.2</mu1>
    <mu2>0.2</mu2>
    <selfCollide>true</selfCollide>
    <material>Gazebo/RedGlow</material>
  </gazebo>

  <material name="black_color">
    <color rgba="0.0 0.0 0.0 1.0"/>
  </material>
  <material name="blue_color">
    <color rgba="0.0 0.0 0.8 1.0"/>
  </material>
  <material name="green_color">
    <color rgba="0.0 0.8 0.0 1.0"/>
  </material>
  <material name="grey_color">
    <color rgba="0.2 0.2 0.2 1.0"/>
  </material>
  <material name="orange_color">
    <color rgba="1.0 0.423529411765 0.0392156862745 1.0"/>
  </material>
  <material name="brown_color">
    <color rgba="0.870588235294 0.811764705882 0.764705882353 1.0"/>
  </material>
  <material name="red_color">
    <color rgba="0.8 0.0 0.0 1.0"/>
  </material>
  <material name="white_color">
    <color rgba="1.0 1.0 1.0 1.0"/>
  </material>

  <joint name="mentese" type="fixed">
    <origin rpy="0 0 0" xyz="0 0 0"/>
    <parent link="base_link"/>
    <child link="robot_base"/>
  </joint>

  <link name="robot_base">
    <inertial>
      <origin rpy="0 0 0" xyz="0.418034980025246 -0.000782333391554025 0.208032037887691"/>
      <mass value="2.671604406"/>
      <inertia ixx="597292.332990132E-06"
        ixy="-127.888886625E-06"
        ixz="-449.533173253E-06"
        iyy="492845.336258658E-06"
        iyz="208211.781374429E-06"
        izz="124452.547442394E-06" />
    </inertial>
    <visual>
      <origin rpy="0 0 0" xyz="0 0 0"/>
      <geometry>
        <mesh filename="package://husky_description/meshes/robot_arm/robot_base.STL"/>
      </geometry>
      <material name="blue_color"/>
    </visual>
    <collision>
      <origin rpy="0 0 0" xyz="0 0 0"/>
      <geometry>
        <mesh filename="package://husky_description/meshes/robot_arm/robot_base.STL"/>
      </geometry>
    </collision>
  </link>

  <link name="robot_base_link">
    <inertial>
      <origin rpy="0 0 0" xyz="2.9353E-05 0.0014524 0.020952"/>
      <mass value="0.284301995"/>
      <inertia ixx="74981.607004731E-06" ixy="129.637517614E-06" ixz="184.504037616E-06" iyy="50913.942818055E-06" iyz="34974.529901905E-06" izz="24718.839862861E-06"/>
    </inertial>
    <visual>
      <origin rpy="0 0 0" xyz="0 0 0"/>
      <geometry>
        <mesh filename="package://husky_description/meshes/robot_arm/robot_base_link.STL"/>
      </geometry>
      <material name="grey_color"/>
    </visual>
    <collision>
      <origin rpy="0 0 0" xyz="0 0 0"/>
      <geometry>
        <mesh filename="package://husky_description/meshes/robot_arm/robot_base_link.STL"/>
      </geometry>
    </collision>
  </link>

  <joint name="base_joint" type="revolute">
    <origin rpy="0 0 0.0978090533" xyz="0.420858898939541 0 0.271325"/>
    <parent link="robot_base"/>
    <child link="robot_base_link"/>
    <axis xyz="0 0 1"/>
    <limit effort="1.27" lower="-1.57" upper="1.57" velocity="5"/> <!--0.0978090533-->
  </joint>

  <link name="shoulder_link">
    <inertial>
      <origin rpy="0 0 0" xyz="0.0496940363994199 0.0860767640737393 -0.0287834279473539"/>
      <mass value="0.179404445"/>
      <inertia ixx="70683.501110674E-06" ixy="-2162.283442012E-06" ixz="-2423.233463483E-06" iyy="39816.613776127E-06" iyz="34996.406150738E-06" izz="31454.214124666E-06"/>
    </inertial>
    <visual>
      <origin rpy="0 0 0" xyz="0 0 0"/>
      <geometry>
        <mesh filename="package://husky_description/meshes/robot_arm/shoulder_link.STL"/>
      </geometry>
      <material name="black_color"/>
    </visual>
    <collision>
      <origin rpy="0 0 0" xyz="0 0 0"/>
      <geometry>
        <mesh filename="package://husky_description/meshes/robot_arm/shoulder_link.STL"/>
      </geometry>
    </collision>
  </link>

  <joint name="shoulder_joint" type="revolute">
    <origin rpy="1.5707963267949 -0.531818679 -0.0978090532272731" xyz="-0.00517561841352504 -0.0527466868536555 0.0554588989435411"/>
    <parent link="robot_base_link"/>
    <child link="shoulder_link"/>
    <axis xyz="0 0 1"/>
    <limit effort="3.92" lower="-1.57" upper="1.57" velocity="5"/> <!--0.531818679-->
  </joint>

  <link name="elbow_link">
    <inertial>
      <origin rpy="0 0 0" xyz="0.055766 -1.1102E-16 -0.033121"/>
      <mass value="0.142339012"/>
      <inertia ixx="86002.721511000E-06" ixy="-2599.811126712E-06" ixz="-2670.353537520E-06" iyy="44389.787937698E-06" iyz="42969.381360791E-06" izz="42007.842775044E-06"/>
    </inertial>
    <visual>
      <origin rpy="0 0 0" xyz="0 0 0"/>
      <geometry>
        <mesh filename="package://husky_description/meshes/robot_arm/elbow_link.STL"/>
      </geometry>
      <material name="orange_color"/>
    </visual>
    <collision>
      <origin rpy="0 0 0" xyz="0 0 0"/>
      <geometry>
        <mesh filename="package://husky_description/meshes/robot_arm/elbow_link.STL"/>
      </geometry>
    </collision>
  </link>

  <joint name="elbow_joint" type="revolute">
    <origin rpy="0 0 1.047197551" xyz="0.0999999999999986 0.173205080756889 0.000799999999999731"/> <!--0.225743189  /// 821454362391037-->
    <parent link="shoulder_link"/>
    <child link="elbow_link"/>
    <axis xyz="0 0 1"/>
    <limit effort="1.27" lower="-1.57" upper="1.57" velocity="5"/>
  </joint>

  <link name="wrist_link">
    <inertial>
      <origin rpy="0 0 0" xyz="0.039602 -0.0019126 -0.029529"/>
      <mass value="0.079971023"/>
      <inertia ixx="60403.006518799E-06" ixy="-2126.614477647E-06" ixz="-2168.999298315E-06" iyy="31021.227505565E-06" iyz="30175.086448661E-06" izz="29771.350623545E-06"/>
    </inertial>
    <visual>
      <origin rpy="0 0 0" xyz="0 0 0"/>
      <geometry>
        <mesh filename="package://husky_description/meshes/robot_arm/wrist_link.STL"/>
      </geometry>
      <material name="orange_color"/>
    </visual>
    <collision>
      <origin rpy="0 0 0" xyz="0 0 0"/>
      <geometry>
        <mesh filename="package://husky_description/meshes/robot_arm/wrist_link.STL"/>
      </geometry>
    </collision>
  </link>

  <joint name="wrist_joint" type="revolute">
    <origin rpy="0 0 0" xyz="0.109318397887081 0 0"/>
    <parent link="elbow_link"/>
    <child link="wrist_link"/>
    <axis xyz="0 0 1"/>
    <limit effort="1.27" lower="-1.57" upper="1.57" velocity="5"/>
  </joint>

  <link name="gripper_link">
    <inertial>
      <origin rpy="0 0 0" xyz="-0.021967 0.0017166 0.04277"/>
      <mass value="0.077182848"/>
      <inertia ixx="65634.640996782E-06" ixy="-2334.141579078E-06" ixz="-2273.536267825E-06" iyy="32630.850534936E-06" iyz="32684.221370422E-06" izz="33903.390597223E-06"/>
    </inertial>
    <visual>
      <origin rpy="0 0 0" xyz="0 0 0"/>
      <geometry>
        <mesh filename="package://husky_description/meshes/robot_arm/gripper_link.STL"/>
      </geometry>
      <material name="green_color"/>
    </visual>
    <collision>
      <origin rpy="0 0 0" xyz="0 0 0"/>
      <geometry>
        <mesh filename="package://husky_description/meshes/robot_arm/gripper_link.STL"/>
      </geometry>
    </collision>
  </link>

  <joint name="gripper_joint" type="fixed">
    <origin rpy="-1.5707963267949 0.0717156812972501 -1.5707963267949" xyz="0.0500826452124297 -0.00815553877386262 -0.0296915667993771"/>
    <parent link="wrist_link"/>
    <child link="gripper_link"/>
    <axis xyz="0 0 0"/>
  </joint>

  <link name="camera_link">
    <inertial>
      <origin rpy="0 0 0" xyz="0.014833 0.00040086 -0.007691"/>
      <mass value="0.03589"/>
      <inertia ixx="3.5126E-06" ixy="-4.8443E-09" ixz="-1.7271E-08" iyy="1.1161E-05" iyz="1.1342E-07" izz="1.0856E-05"/>
    </inertial>
    <visual>
      <origin rpy="0 0 0" xyz="0 0 0"/>
      <geometry>
        <mesh filename="package://husky_description/meshes/robot_arm/camera_link.STL"/>
      </geometry>
      <material name="green_color"/>
    </visual>
    <collision>
      <origin rpy="0 0 0" xyz="0 0 0"/>
      <geometry>
        <mesh filename="package://husky_description/meshes/robot_arm/camera_link.STL"/>
      </geometry>
    </collision>
  </link>

  <joint name="camera_optical_joint" type="fixed">
    <origin xyz="0 0 0" rpy= "0 1.5708 0"/>
    <parent link="camera_link"/>
    <child link="camera_link_optical"/>
  </joint>

  <link name="camera_link_optical">
  </link>


  <joint name="camera_joint" type="fixed">
    <origin rpy="0.0 0.1 0" xyz="0.52693 0 0.13226"/>
    <parent link="robot_base"/>
    <child link="camera_link"/>
    <axis xyz="0 0 0"/>
  </joint>

  <link name="lidar_link">
    <inertial>
      <origin rpy="0 0 0" xyz="0.0005 -0.00067912 -0.024176"/>
      <mass value="0.270"/>
      <inertia ixx="2.632e-4" ixy="0" ixz="0" iyy="2.632e-4" iyz="0" izz="1.62e-4"/>
    </inertial>
    <visual>
      <origin rpy="0 0 0" xyz="0 0 0"/>
      <geometry>
        <mesh filename="package://husky_description/meshes/robot_arm/lidar_link.STL"/>
      </geometry>
      <material name="orange_color"/>
    </visual>
    <collision>
      <origin rpy="0 0 0" xyz="0 0 0"/>
      <geometry>
        <mesh filename="package://husky_description/meshes/robot_arm/hokuyo.dae"/>
      </geometry>
    </collision>
  </link>

  <joint name="lidar_joint" type="fixed">
    <origin rpy="0 0 0" xyz="0.47269 0 0.20419"/>
    <parent link="robot_base"/>
    <child link="lidar_link"/>
    <axis xyz="0 0 0"/>
  </joint>

<!-- Transmission -->
<xacro:transmission_block joint_name="base_joint"/>
<xacro:transmission_block joint_name="shoulder_joint"/>
<xacro:transmission_block joint_name="elbow_joint"/>
<xacro:transmission_block joint_name="wrist_joint"/>


<!-- Gazebo Things -->

 

 <gazebo reference="camera_link">
    <sensor type="camera" name="camera">
      <update_rate>30.0</update_rate>
      <camera name="head">
        <horizontal_fov>1.04719755</horizontal_fov>
        <image>
          <width>800</width>
          <height>800</height>
          <format>R8G8B8</format>
        </image>
        <clip>
          <near>0.009</near>
          <far>1000</far>
        </clip>
        <noise>
          <type>gaussian</type>
          <!-- Noise is sampled independently per pixel on each frame.
               That pixel's noise value is added to each of its color
               channels, which at that point lie in the range [0,1]. -->
          <mean>0.0</mean>
          <stddev>0.007</stddev>
        </noise>
      </camera>
      <plugin name="camera_controller" filename="libgazebo_ros_camera.so">
        <alwaysOn>true</alwaysOn>
        <updateRate>0.0</updateRate>
        <cameraName>/robot_arm/camera</cameraName>
        <imageTopicName>image_raw</imageTopicName>
        <cameraInfoTopicName>camera_info</cameraInfoTopicName>
        <frameName>/camera_link_optical</frameName>
        <hackBaseline>0.07</hackBaseline>
        <distortionK1>0.0</distortionK1>
        <distortionK2>0.0</distortionK2>
        <distortionK3>0.0</distortionK3>
        <distortionT1>0.0</distortionT1>
        <distortionT2>0.0</distortionT2>
      </plugin>
    </sensor>
  </gazebo>

  <gazebo reference="lidar_link">
    <sensor type="ray" name="head_hokuyo_sensor">
      <pose>0 0 0 0 0 0</pose>
      <visualize>true</visualize>
      <update_rate>40</update_rate>
      <ray>
        <scan>
          <horizontal>
            <samples>720</samples>
            <resolution>1</resolution>
            <min_angle>-1.38</min_angle>
            <max_angle>1.38</max_angle>
          </horizontal>
        </scan>
        <range>
          <min>0.10</min>
          <max>30.0</max>
          <resolution>0.01</resolution>
        </range>
        <noise>
          <type>gaussian</type>
          <!-- Noise parameters based on published spec for Hokuyo laser
               achieving "+-30mm" accuracy at range < 10m.  A mean of 0.0m and
               stddev of 0.01m will put 99.7% of samples within 0.03m of the true
               reading. -->
          <mean>0.0</mean>
          <stddev>0.01</stddev>
        </noise>
      </ray>
      <plugin name="gazebo_ros_head_hokuyo_controller" filename="libgazebo_ros_laser.so">
        <topicName>scan</topicName>
        <frameName>lidar_link</frameName>
      </plugin>
    </sensor>
  </gazebo>



</robot>

